<sdf version='1.7'>
  <world name='default'>
    <light name='sun' type='directional'>
      <cast_shadows>1</cast_shadows>
      <pose>0 0 10 0 -0 0</pose>
      <diffuse>0.8 0.8 0.8 1</diffuse>
      <specular>0.2 0.2 0.2 1</specular>
      <attenuation>
        <range>1000</range>
        <constant>0.9</constant>
        <linear>0.01</linear>
        <quadratic>0.001</quadratic>
      </attenuation>
      <direction>-0.5 0.1 -0.9</direction>
      <spot>
        <inner_angle>0</inner_angle>
        <outer_angle>0</outer_angle>
        <falloff>0</falloff>
      </spot>
    </light>
    <model name='ground_plane'>
      <static>1</static>
      <link name='link'>
        <collision name='collision'>
          <geometry>
            <plane>
              <normal>0 0 1</normal>
              <size>100 100</size>
            </plane>
          </geometry>
          <surface>
            <contact>
              <collide_bitmask>65535</collide_bitmask>
              <ode/>
            </contact>
            <friction>
              <ode>
                <mu>100</mu>
                <mu2>50</mu2>
              </ode>
              <torsional>
                <ode/>
              </torsional>
            </friction>
            <bounce/>
          </surface>
          <max_contacts>10</max_contacts>
        </collision>
        <visual name='visual'>
          <cast_shadows>0</cast_shadows>
          <geometry>
            <plane>
              <normal>0 0 1</normal>
              <size>100 100</size>
            </plane>
          </geometry>
          <material>
            <script>
              <uri>file://media/materials/scripts/gazebo.material</uri>
              <name>Gazebo/Grey</name>
            </script>
          </material>
        </visual>
        <self_collide>0</self_collide>
        <enable_wind>0</enable_wind>
        <kinematic>0</kinematic>
      </link>
    </model>
    <gravity>0 0 -9.8</gravity>
    <magnetic_field>6e-06 2.3e-05 -4.2e-05</magnetic_field>
    <atmosphere type='adiabatic'/>
    <physics type='ode'>
      <max_step_size>0.001</max_step_size>
      <real_time_factor>1</real_time_factor>
      <real_time_update_rate>1000</real_time_update_rate>
    </physics>
    <scene>
      <ambient>0.4 0.4 0.4 1</ambient>
      <background>0.7 0.7 0.7 1</background>
      <shadows>1</shadows>
    </scene>
    <wind/>
    <spherical_coordinates>
      <surface_model>EARTH_WGS84</surface_model>
      <latitude_deg>0</latitude_deg>
      <longitude_deg>0</longitude_deg>
      <elevation>0</elevation>
      <heading_deg>0</heading_deg>
    </spherical_coordinates>
    <model name='botx_world'>
      <pose>0.323182 -0.055349 0 0 -0 0</pose>
      <link name='Wall_1'>
        <collision name='Wall_1_Collision'>
          <geometry>
            <box>
              <size>8.25 0.15 2.5</size>
            </box>
          </geometry>
          <pose>0 0 1.25 0 -0 0</pose>
          <max_contacts>10</max_contacts>
          <surface>
            <contact>
              <ode/>
            </contact>
            <bounce/>
            <friction>
              <torsional>
                <ode/>
              </torsional>
              <ode/>
            </friction>
          </surface>
        </collision>
        <visual name='Wall_1_Visual'>
          <pose>0 0 1.25 0 -0 0</pose>
          <geometry>
            <box>
              <size>8.25 0.15 2.5</size>
            </box>
          </geometry>
          <material>
            <script>
              <uri>file://media/materials/scripts/gazebo.material</uri>
              <name>Gazebo/Bricks</name>
            </script>
            <ambient>1 1 1 1</ambient>
          </material>
          <meta>
            <layer>0</layer>
          </meta>
        </visual>
        <pose>-7.65341 -1.77159 0 0 -0 -1.5708</pose>
        <self_collide>0</self_collide>
        <enable_wind>0</enable_wind>
        <kinematic>0</kinematic>
      </link>
      <link name='Wall_10'>
        <collision name='Wall_10_Collision'>
          <geometry>
            <box>
              <size>3.25 0.15 2.5</size>
            </box>
          </geometry>
          <pose>0 0 1.25 0 -0 0</pose>
          <max_contacts>10</max_contacts>
          <surface>
            <contact>
              <ode/>
            </contact>
            <bounce/>
            <friction>
              <torsional>
                <ode/>
              </torsional>
              <ode/>
            </friction>
          </surface>
        </collision>
        <visual name='Wall_10_Visual'>
          <pose>0 0 1.25 0 -0 0</pose>
          <geometry>
            <box>
              <size>3.25 0.15 2.5</size>
            </box>
          </geometry>
          <material>
            <script>
              <uri>file://media/materials/scripts/gazebo.material</uri>
              <name>Gazebo/Bricks</name>
            </script>
            <ambient>1 1 1 1</ambient>
          </material>
          <meta>
            <layer>0</layer>
          </meta>
        </visual>
        <pose>5.87961 1.44539 0 0 -0 0</pose>
        <self_collide>0</self_collide>
        <enable_wind>0</enable_wind>
        <kinematic>0</kinematic>
      </link>
      <link name='Wall_11'>
        <collision name='Wall_11_Collision'>
          <geometry>
            <box>
              <size>4.5 0.15 2.5</size>
            </box>
          </geometry>
          <pose>0 0 1.25 0 -0 0</pose>
          <max_contacts>10</max_contacts>
          <surface>
            <contact>
              <ode/>
            </contact>
            <bounce/>
            <friction>
              <torsional>
                <ode/>
              </torsional>
              <ode/>
            </friction>
          </surface>
        </collision>
        <visual name='Wall_11_Visual'>
          <pose>0 0 1.25 0 -0 0</pose>
          <geometry>
            <box>
              <size>4.5 0.15 2.5</size>
            </box>
          </geometry>
          <material>
            <script>
              <uri>file://media/materials/scripts/gazebo.material</uri>
              <name>Gazebo/Bricks</name>
            </script>
            <ambient>1 1 1 1</ambient>
          </material>
          <meta>
            <layer>0</layer>
          </meta>
        </visual>
        <pose>7.42961 3.62039 0 0 -0 1.5708</pose>
        <self_collide>0</self_collide>
        <enable_wind>0</enable_wind>
        <kinematic>0</kinematic>
      </link>
      <link name='Wall_12'>
        <collision name='Wall_12_Collision'>
          <geometry>
            <box>
              <size>8.5 0.15 2.5</size>
            </box>
          </geometry>
          <pose>0 0 1.25 0 -0 0</pose>
          <max_contacts>10</max_contacts>
          <surface>
            <contact>
              <ode/>
            </contact>
            <bounce/>
            <friction>
              <torsional>
                <ode/>
              </torsional>
              <ode/>
            </friction>
          </surface>
        </collision>
        <visual name='Wall_12_Visual'>
          <pose>0 0 1.25 0 -0 0</pose>
          <geometry>
            <box>
              <size>8.5 0.15 2.5</size>
            </box>
          </geometry>
          <material>
            <script>
              <uri>file://media/materials/scripts/gazebo.material</uri>
              <name>Gazebo/Bricks</name>
            </script>
            <ambient>1 1 1 1</ambient>
          </material>
          <meta>
            <layer>0</layer>
          </meta>
        </visual>
        <pose>3.25461 5.79539 0 0 -0 3.14159</pose>
        <self_collide>0</self_collide>
        <enable_wind>0</enable_wind>
        <kinematic>0</kinematic>
      </link>
      <link name='Wall_13'>
        <collision name='Wall_13_Collision'>
          <geometry>
            <box>
              <size>7.74623 0.15 2.5</size>
            </box>
          </geometry>
          <pose>0 0 1.25 0 -0 0</pose>
          <max_contacts>10</max_contacts>
          <surface>
            <contact>
              <ode/>
            </contact>
            <bounce/>
            <friction>
              <torsional>
                <ode/>
              </torsional>
              <ode/>
            </friction>
          </surface>
        </collision>
        <visual name='Wall_13_Visual'>
          <pose>0 0 1.25 0 -0 0</pose>
          <geometry>
            <box>
              <size>7.74623 0.15 2.5</size>
            </box>
          </geometry>
          <material>
            <script>
              <uri>file://media/materials/scripts/gazebo.material</uri>
              <name>Gazebo/Bricks</name>
            </script>
            <ambient>1 1 1 1</ambient>
          </material>
          <meta>
            <layer>0</layer>
          </meta>
        </visual>
        <pose>-4.2869 4.0369 0 0 -0 -2.66023</pose>
        <self_collide>0</self_collide>
        <enable_wind>0</enable_wind>
        <kinematic>0</kinematic>
      </link>
      <link name='Wall_2'>
        <collision name='Wall_2_Collision'>
          <geometry>
            <box>
              <size>3.25 0.15 2.5</size>
            </box>
          </geometry>
          <pose>0 0 1.25 0 -0 0</pose>
          <max_contacts>10</max_contacts>
          <surface>
            <contact>
              <ode/>
            </contact>
            <bounce/>
            <friction>
              <torsional>
                <ode/>
              </torsional>
              <ode/>
            </friction>
          </surface>
        </collision>
        <visual name='Wall_2_Visual'>
          <pose>0 0 1.25 0 -0 0</pose>
          <geometry>
            <box>
              <size>3.25 0.15 2.5</size>
            </box>
          </geometry>
          <material>
            <script>
              <uri>file://media/materials/scripts/gazebo.material</uri>
              <name>Gazebo/Bricks</name>
            </script>
            <ambient>1 1 1 1</ambient>
          </material>
          <meta>
            <layer>0</layer>
          </meta>
        </visual>
        <pose>-6.10341 -5.82159 0 0 -0 0</pose>
        <self_collide>0</self_collide>
        <enable_wind>0</enable_wind>
        <kinematic>0</kinematic>
      </link>
      <link name='Wall_3'>
        <collision name='Wall_3_Collision'>
          <geometry>
            <box>
              <size>4.25 0.15 2.5</size>
            </box>
          </geometry>
          <pose>0 0 1.25 0 -0 0</pose>
          <max_contacts>10</max_contacts>
          <surface>
            <contact>
              <ode/>
            </contact>
            <bounce/>
            <friction>
              <torsional>
                <ode/>
              </torsional>
              <ode/>
            </friction>
          </surface>
        </collision>
        <visual name='Wall_3_Visual'>
          <pose>0 0 1.25 0 -0 0</pose>
          <geometry>
            <box>
              <size>4.25 0.15 2.5</size>
            </box>
          </geometry>
          <material>
            <script>
              <uri>file://media/materials/scripts/gazebo.material</uri>
              <name>Gazebo/Bricks</name>
            </script>
            <ambient>1 1 1 1</ambient>
          </material>
          <meta>
            <layer>0</layer>
          </meta>
        </visual>
        <pose>-4.55341 -3.77159 0 0 -0 1.5708</pose>
        <self_collide>0</self_collide>
        <enable_wind>0</enable_wind>
        <kinematic>0</kinematic>
      </link>
      <link name='Wall_4'>
        <collision name='Wall_4_Collision'>
          <geometry>
            <box>
              <size>3.75 0.15 2.5</size>
            </box>
          </geometry>
          <pose>0 0 1.25 0 -0 0</pose>
          <max_contacts>10</max_contacts>
          <surface>
            <contact>
              <ode/>
            </contact>
            <bounce/>
            <friction>
              <torsional>
                <ode/>
              </torsional>
              <ode/>
            </friction>
          </surface>
        </collision>
        <visual name='Wall_4_Visual'>
          <pose>0 0 1.25 0 -0 0</pose>
          <geometry>
            <box>
              <size>3.75 0.15 2.5</size>
            </box>
          </geometry>
          <material>
            <script>
              <uri>file://media/materials/scripts/gazebo.material</uri>
              <name>Gazebo/Bricks</name>
            </script>
            <ambient>1 1 1 1</ambient>
          </material>
          <meta>
            <layer>0</layer>
          </meta>
        </visual>
        <pose>-2.75341 -1.72159 0 0 -0 0</pose>
        <self_collide>0</self_collide>
        <enable_wind>0</enable_wind>
        <kinematic>0</kinematic>
      </link>
      <link name='Wall_5'>
        <collision name='Wall_5_Collision'>
          <geometry>
            <box>
              <size>5.5 0.15 2.5</size>
            </box>
          </geometry>
          <pose>0 0 1.25 0 -0 0</pose>
          <max_contacts>10</max_contacts>
          <surface>
            <contact>
              <ode/>
            </contact>
            <bounce/>
            <friction>
              <torsional>
                <ode/>
              </torsional>
              <ode/>
            </friction>
          </surface>
        </collision>
        <visual name='Wall_5_Visual'>
          <pose>0 0 1.25 0 -0 0</pose>
          <geometry>
            <box>
              <size>5.5 0.15 2.5</size>
            </box>
          </geometry>
          <material>
            <script>
              <uri>file://media/materials/scripts/gazebo.material</uri>
              <name>Gazebo/Bricks</name>
            </script>
            <ambient>1 1 1 1</ambient>
          </material>
          <meta>
            <layer>0</layer>
          </meta>
        </visual>
        <pose>0.938101 -3.6131 0 0 -0 -0.785398</pose>
        <self_collide>0</self_collide>
        <enable_wind>0</enable_wind>
        <kinematic>0</kinematic>
      </link>
      <link name='Wall_6'>
        <collision name='Wall_6_Collision'>
          <geometry>
            <box>
              <size>5 0.15 2.5</size>
            </box>
          </geometry>
          <pose>0 0 1.25 0 -0 0</pose>
          <max_contacts>10</max_contacts>
          <surface>
            <contact>
              <ode/>
            </contact>
            <bounce/>
            <friction>
              <torsional>
                <ode/>
              </torsional>
              <ode/>
            </friction>
          </surface>
        </collision>
        <visual name='Wall_6_Visual'>
          <pose>0 0 1.25 0 -0 0</pose>
          <geometry>
            <box>
              <size>5 0.15 2.5</size>
            </box>
          </geometry>
          <material>
            <script>
              <uri>file://media/materials/scripts/gazebo.material</uri>
              <name>Gazebo/Bricks</name>
            </script>
            <ambient>1 1 1 1</ambient>
          </material>
          <meta>
            <layer>0</layer>
          </meta>
        </visual>
        <pose>5.25461 -5.50461 0 0 -0 0</pose>
        <self_collide>0</self_collide>
        <enable_wind>0</enable_wind>
        <kinematic>0</kinematic>
      </link>
      <link name='Wall_7'>
        <collision name='Wall_7_Collision'>
          <geometry>
            <box>
              <size>5.5 0.15 2.5</size>
            </box>
          </geometry>
          <pose>0 0 1.25 0 -0 0</pose>
          <max_contacts>10</max_contacts>
          <surface>
            <contact>
              <ode/>
            </contact>
            <bounce/>
            <friction>
              <torsional>
                <ode/>
              </torsional>
              <ode/>
            </friction>
          </surface>
        </collision>
        <visual name='Wall_7_Visual'>
          <pose>0 0 1.25 0 -0 0</pose>
          <geometry>
            <box>
              <size>5.5 0.15 2.5</size>
            </box>
          </geometry>
          <material>
            <script>
              <uri>file://media/materials/scripts/gazebo.material</uri>
              <name>Gazebo/Bricks</name>
            </script>
            <ambient>1 1 1 1</ambient>
          </material>
          <meta>
            <layer>0</layer>
          </meta>
        </visual>
        <pose>7.67961 -2.82961 0 0 -0 1.5708</pose>
        <self_collide>0</self_collide>
        <enable_wind>0</enable_wind>
        <kinematic>0</kinematic>
      </link>
      <link name='Wall_8'>
        <collision name='Wall_8_Collision'>
          <geometry>
            <box>
              <size>3.5 0.15 2.5</size>
            </box>
          </geometry>
          <pose>0 0 1.25 0 -0 0</pose>
          <max_contacts>10</max_contacts>
          <surface>
            <contact>
              <ode/>
            </contact>
            <bounce/>
            <friction>
              <torsional>
                <ode/>
              </torsional>
              <ode/>
            </friction>
          </surface>
        </collision>
        <visual name='Wall_8_Visual'>
          <pose>0 0 1.25 0 -0 0</pose>
          <geometry>
            <box>
              <size>3.5 0.15 2.5</size>
            </box>
          </geometry>
          <material>
            <script>
              <uri>file://media/materials/scripts/gazebo.material</uri>
              <name>Gazebo/Bricks</name>
            </script>
            <ambient>1 1 1 1</ambient>
          </material>
          <meta>
            <layer>0</layer>
          </meta>
        </visual>
        <pose>6.00461 -0.154611 0 0 -0 3.14159</pose>
        <self_collide>0</self_collide>
        <enable_wind>0</enable_wind>
        <kinematic>0</kinematic>
      </link>
      <link name='Wall_9'>
        <collision name='Wall_9_Collision'>
          <geometry>
            <box>
              <size>1.75 0.15 2.5</size>
            </box>
          </geometry>
          <pose>0 0 1.25 0 -0 0</pose>
          <max_contacts>10</max_contacts>
          <surface>
            <contact>
              <ode/>
            </contact>
            <bounce/>
            <friction>
              <torsional>
                <ode/>
              </torsional>
              <ode/>
            </friction>
          </surface>
        </collision>
        <visual name='Wall_9_Visual'>
          <pose>0 0 1.25 0 -0 0</pose>
          <geometry>
            <box>
              <size>1.75 0.15 2.5</size>
            </box>
          </geometry>
          <material>
            <script>
              <uri>file://media/materials/scripts/gazebo.material</uri>
              <name>Gazebo/Bricks</name>
            </script>
            <ambient>1 1 1 1</ambient>
          </material>
          <meta>
            <layer>0</layer>
          </meta>
        </visual>
        <pose>4.32961 0.645389 0 0 -0 1.5708</pose>
        <self_collide>0</self_collide>
        <enable_wind>0</enable_wind>
        <kinematic>0</kinematic>
      </link>
      <static>1</static>
    </model>
    <model name='polaris_ranger_ev'>
      <link name='chassis'>
        <inertial>
          <mass>720</mass>
          <inertia>
            <ixx>140</ixx>
            <ixy>0</ixy>
            <iyy>550</iyy>
            <ixz>0</ixz>
            <iyz>0</iyz>
            <izz>550</izz>
          </inertia>
          <pose>0.1 0 0.4 0 -0 0</pose>
        </inertial>
        <visual name='visual'>
          <pose>0 0 0 0 0 -1.5708</pose>
          <geometry>
            <mesh>
              <uri>model://polaris_ranger_ev/meshes/polaris.dae</uri>
              <submesh>
                <name>Ranger</name>
                <center>0</center>
              </submesh>
            </mesh>
          </geometry>
          <material>
            <script>
              <uri>model://polaris_ranger_ev/materials/scripts</uri>
              <uri>model://polaris_ranger_ev/materials/textures</uri>
              <name>Polaris/Diffuse</name>
            </script>
          </material>
        </visual>
        <collision name='chassis_bottom'>
          <pose>0.1 0 0.37 0 -0 0</pose>
          <geometry>
            <box>
              <size>1.5 1.34 0.06</size>
            </box>
          </geometry>
          <max_contacts>10</max_contacts>
          <surface>
            <contact>
              <ode/>
            </contact>
            <bounce/>
            <friction>
              <torsional>
                <ode/>
              </torsional>
              <ode/>
            </friction>
          </surface>
        </collision>
        <collision name='cargo_bottom'>
          <pose>-0.9 0 0.9 0 -0 0</pose>
          <geometry>
            <box>
              <size>0.9 1.2 0.01</size>
            </box>
          </geometry>
          <max_contacts>10</max_contacts>
          <surface>
            <contact>
              <ode/>
            </contact>
            <bounce/>
            <friction>
              <torsional>
                <ode/>
              </torsional>
              <ode/>
            </friction>
          </surface>
        </collision>
        <collision name='cargo_front'>
          <pose>-0.45 0 1.025 0 -0 0</pose>
          <geometry>
            <box>
              <size>0.05 1.2 0.25</size>
            </box>
          </geometry>
          <max_contacts>10</max_contacts>
          <surface>
            <contact>
              <ode/>
            </contact>
            <bounce/>
            <friction>
              <torsional>
                <ode/>
              </torsional>
              <ode/>
            </friction>
          </surface>
        </collision>
        <collision name='cargo_back'>
          <pose>-1.35 0 1.025 0 -0 0</pose>
          <geometry>
            <box>
              <size>0.05 1.2 0.25</size>
            </box>
          </geometry>
          <max_contacts>10</max_contacts>
          <surface>
            <contact>
              <ode/>
            </contact>
            <bounce/>
            <friction>
              <torsional>
                <ode/>
              </torsional>
              <ode/>
            </friction>
          </surface>
        </collision>
        <collision name='cargo_left'>
          <pose>-0.9 0.6 1.025 0 -0 0</pose>
          <geometry>
            <box>
              <size>0.9 0.05 0.25</size>
            </box>
          </geometry>
          <max_contacts>10</max_contacts>
          <surface>
            <contact>
              <ode/>
            </contact>
            <bounce/>
            <friction>
              <torsional>
                <ode/>
              </torsional>
              <ode/>
            </friction>
          </surface>
        </collision>
        <collision name='cargo_right'>
          <pose>-0.9 -0.6 1.025 0 -0 0</pose>
          <geometry>
            <box>
              <size>0.9 0.05 0.25</size>
            </box>
          </geometry>
          <max_contacts>10</max_contacts>
          <surface>
            <contact>
              <ode/>
            </contact>
            <bounce/>
            <friction>
              <torsional>
                <ode/>
              </torsional>
              <ode/>
            </friction>
          </surface>
        </collision>
        <collision name='seat'>
          <pose>-0.1 0 0.56 0 -0 0</pose>
          <geometry>
            <box>
              <size>0.6 1.22 0.5</size>
            </box>
          </geometry>
          <surface>
            <contact>
              <ode>
                <min_depth>0.01</min_depth>
              </ode>
            </contact>
            <bounce/>
            <friction>
              <torsional>
                <ode/>
              </torsional>
              <ode/>
            </friction>
          </surface>
          <max_contacts>10</max_contacts>
        </collision>
        <collision name='mud_seat'>
          <pose>-0.1 0 0.81 0 -0 0</pose>
          <geometry>
            <box>
              <size>0.6 1.15 0.1</size>
            </box>
          </geometry>
          <surface>
            <contact>
              <collide_without_contact>1</collide_without_contact>
              <ode/>
            </contact>
            <bounce/>
            <friction>
              <torsional>
                <ode/>
              </torsional>
              <ode/>
            </friction>
          </surface>
          <max_contacts>10</max_contacts>
        </collision>
        <sensor name='seat_contact' type='contact'>
          <always_on>1</always_on>
          <update_rate>1000</update_rate>
          <contact>
            <collision>mud_seat</collision>
            <topic>__default_topic__</topic>
          </contact>
        </sensor>
        <collision name='seat_back'>
          <pose>-0.3 0 1.125 0 -0.2 0</pose>
          <geometry>
            <box>
              <size>0.06 1 0.4</size>
            </box>
          </geometry>
          <max_contacts>10</max_contacts>
          <surface>
            <contact>
              <ode/>
            </contact>
            <bounce/>
            <friction>
              <torsional>
                <ode/>
              </torsional>
              <ode/>
            </friction>
          </surface>
        </collision>
        <collision name='engine'>
          <pose>1.05 0 0.7 0 -0 0</pose>
          <geometry>
            <box>
              <size>0.58 1 0.8</size>
            </box>
          </geometry>
          <max_contacts>10</max_contacts>
          <surface>
            <contact>
              <ode/>
            </contact>
            <bounce/>
            <friction>
              <torsional>
                <ode/>
              </torsional>
              <ode/>
            </friction>
          </surface>
        </collision>
        <collision name='handle_left_middle'>
          <pose>-0.3 0.61 1.055 0 -0.2 0</pose>
          <geometry>
            <cylinder>
              <radius>0.02</radius>
              <length>0.17</length>
            </cylinder>
          </geometry>
          <max_contacts>10</max_contacts>
          <surface>
            <contact>
              <ode/>
            </contact>
            <bounce/>
            <friction>
              <torsional>
                <ode/>
              </torsional>
              <ode/>
            </friction>
          </surface>
        </collision>
        <collision name='handle_right_middle'>
          <pose>-0.3 -0.61 1.055 0 -0.2 0</pose>
          <geometry>
            <cylinder>
              <radius>0.02</radius>
              <length>0.17</length>
            </cylinder>
          </geometry>
          <max_contacts>10</max_contacts>
          <surface>
            <contact>
              <ode/>
            </contact>
            <bounce/>
            <friction>
              <torsional>
                <ode/>
              </torsional>
              <ode/>
            </friction>
          </surface>
        </collision>
        <collision name='rollcage_top_left'>
          <pose>0 0.61 1.92 3.14159 1.53159 3.14159</pose>
          <geometry>
            <cylinder>
              <radius>0.03</radius>
              <length>0.68</length>
            </cylinder>
          </geometry>
          <max_contacts>10</max_contacts>
          <surface>
            <contact>
              <ode/>
            </contact>
            <bounce/>
            <friction>
              <torsional>
                <ode/>
              </torsional>
              <ode/>
            </friction>
          </surface>
        </collision>
        <collision name='rollcage_top_right'>
          <pose>0 -0.61 1.92 3.14159 1.53159 3.14159</pose>
          <geometry>
            <cylinder>
              <radius>0.03</radius>
              <length>0.68</length>
            </cylinder>
          </geometry>
          <max_contacts>10</max_contacts>
          <surface>
            <contact>
              <ode/>
            </contact>
            <bounce/>
            <friction>
              <torsional>
                <ode/>
              </torsional>
              <ode/>
            </friction>
          </surface>
        </collision>
        <collision name='rollcage_top_front'>
          <pose>0.325 0 1.89 1.5708 -0 0</pose>
          <geometry>
            <cylinder>
              <radius>0.03</radius>
              <length>1.22</length>
            </cylinder>
          </geometry>
          <max_contacts>10</max_contacts>
          <surface>
            <contact>
              <ode/>
            </contact>
            <bounce/>
            <friction>
              <torsional>
                <ode/>
              </torsional>
              <ode/>
            </friction>
          </surface>
        </collision>
        <collision name='rollcage_top_back'>
          <pose>-0.33 0 1.92 1.5708 -0 0</pose>
          <geometry>
            <cylinder>
              <radius>0.03</radius>
              <length>1.22</length>
            </cylinder>
          </geometry>
          <max_contacts>10</max_contacts>
          <surface>
            <contact>
              <ode/>
            </contact>
            <bounce/>
            <friction>
              <torsional>
                <ode/>
              </torsional>
              <ode/>
            </friction>
          </surface>
        </collision>
        <collision name='rollcage_front_left'>
          <pose>0.54 0.61 1.45 0 -0.44 0</pose>
          <geometry>
            <cylinder>
              <radius>0.03</radius>
              <length>1.04</length>
            </cylinder>
          </geometry>
          <max_contacts>10</max_contacts>
          <surface>
            <contact>
              <ode/>
            </contact>
            <bounce/>
            <friction>
              <torsional>
                <ode/>
              </torsional>
              <ode/>
            </friction>
          </surface>
        </collision>
        <collision name='rollcage_front_right'>
          <pose>0.54 -0.61 1.45 0 -0.44 0</pose>
          <geometry>
            <cylinder>
              <radius>0.03</radius>
              <length>1.04</length>
            </cylinder>
          </geometry>
          <max_contacts>10</max_contacts>
          <surface>
            <contact>
              <ode/>
            </contact>
            <bounce/>
            <friction>
              <torsional>
                <ode/>
              </torsional>
              <ode/>
            </friction>
          </surface>
        </collision>
        <collision name='fender_front_right'>
          <pose>0.64 -0.61 0.7 0 0.35 0</pose>
          <geometry>
            <cylinder>
              <radius>0.03</radius>
              <length>0.72</length>
            </cylinder>
          </geometry>
          <max_contacts>10</max_contacts>
          <surface>
            <contact>
              <ode/>
            </contact>
            <bounce/>
            <friction>
              <torsional>
                <ode/>
              </torsional>
              <ode/>
            </friction>
          </surface>
        </collision>
        <collision name='fender_front_left'>
          <pose>0.64 0.61 0.7 0 0.35 0</pose>
          <geometry>
            <cylinder>
              <radius>0.03</radius>
              <length>0.72</length>
            </cylinder>
          </geometry>
          <max_contacts>10</max_contacts>
          <surface>
            <contact>
              <ode/>
            </contact>
            <bounce/>
            <friction>
              <torsional>
                <ode/>
              </torsional>
              <ode/>
            </friction>
          </surface>
        </collision>
        <collision name='rollcage_back_left'>
          <pose>-0.37 0.61 1.25 0 -0.14 0</pose>
          <geometry>
            <cylinder>
              <radius>0.03</radius>
              <length>0.9</length>
            </cylinder>
          </geometry>
          <max_contacts>10</max_contacts>
          <surface>
            <contact>
              <ode/>
            </contact>
            <bounce/>
            <friction>
              <torsional>
                <ode/>
              </torsional>
              <ode/>
            </friction>
          </surface>
        </collision>
        <collision name='rollcage_back_right'>
          <pose>-0.37 -0.61 1.25 0 -0.14 0</pose>
          <geometry>
            <cylinder>
              <radius>0.03</radius>
              <length>0.9</length>
            </cylinder>
          </geometry>
          <max_contacts>10</max_contacts>
          <surface>
            <contact>
              <ode/>
            </contact>
            <bounce/>
            <friction>
              <torsional>
                <ode/>
              </torsional>
              <ode/>
            </friction>
          </surface>
        </collision>
        <collision name='rollcage_back_midleft'>
          <pose>-0.37 0.155 1.25 0 -0.14 0</pose>
          <geometry>
            <cylinder>
              <radius>0.023</radius>
              <length>0.9</length>
            </cylinder>
          </geometry>
          <max_contacts>10</max_contacts>
          <surface>
            <contact>
              <ode/>
            </contact>
            <bounce/>
            <friction>
              <torsional>
                <ode/>
              </torsional>
              <ode/>
            </friction>
          </surface>
        </collision>
        <collision name='rollcage_back_midright'>
          <pose>-0.37 -0.155 1.25 0 -0.14 0</pose>
          <geometry>
            <cylinder>
              <radius>0.023</radius>
              <length>0.9</length>
            </cylinder>
          </geometry>
          <max_contacts>10</max_contacts>
          <surface>
            <contact>
              <ode/>
            </contact>
            <bounce/>
            <friction>
              <torsional>
                <ode/>
              </torsional>
              <ode/>
            </friction>
          </surface>
        </collision>
        <collision name='rollcage_back_upper_left'>
          <pose>-0.38 0.61 1.82 0 0.4 0</pose>
          <geometry>
            <cylinder>
              <radius>0.03</radius>
              <length>0.29</length>
            </cylinder>
          </geometry>
          <max_contacts>10</max_contacts>
          <surface>
            <contact>
              <ode/>
            </contact>
            <bounce/>
            <friction>
              <torsional>
                <ode/>
              </torsional>
              <ode/>
            </friction>
          </surface>
        </collision>
        <collision name='rollcage_back_upper_right'>
          <pose>-0.38 -0.61 1.82 0 0.4 0</pose>
          <geometry>
            <cylinder>
              <radius>0.03</radius>
              <length>0.29</length>
            </cylinder>
          </geometry>
          <max_contacts>10</max_contacts>
          <surface>
            <contact>
              <ode/>
            </contact>
            <bounce/>
            <friction>
              <torsional>
                <ode/>
              </torsional>
              <ode/>
            </friction>
          </surface>
        </collision>
        <collision name='rollcage_back_upper_midleft'>
          <pose>-0.38 0.155 1.82 0 0.4 0</pose>
          <geometry>
            <cylinder>
              <radius>0.023</radius>
              <length>0.29</length>
            </cylinder>
          </geometry>
          <max_contacts>10</max_contacts>
          <surface>
            <contact>
              <ode/>
            </contact>
            <bounce/>
            <friction>
              <torsional>
                <ode/>
              </torsional>
              <ode/>
            </friction>
          </surface>
        </collision>
        <collision name='rollcage_back_upper_midright'>
          <pose>-0.38 -0.155 1.82 0 0.4 0</pose>
          <geometry>
            <cylinder>
              <radius>0.023</radius>
              <length>0.29</length>
            </cylinder>
          </geometry>
          <max_contacts>10</max_contacts>
          <surface>
            <contact>
              <ode/>
            </contact>
            <bounce/>
            <friction>
              <torsional>
                <ode/>
              </torsional>
              <ode/>
            </friction>
          </surface>
        </collision>
        <self_collide>0</self_collide>
        <enable_wind>0</enable_wind>
        <kinematic>0</kinematic>
      </link>
      <link name='rear_right_wheel'>
        <pose>-0.85 -0.6 0.32 1.52 -0 0</pose>
        <inertial>
          <mass>12</mass>
          <inertia>
            <ixx>0.5</ixx>
            <ixy>0</ixy>
            <iyy>0.5</iyy>
            <ixz>0</ixz>
            <iyz>0</iyz>
            <izz>1</izz>
          </inertia>
          <pose>0 0 0 0 -0 0</pose>
        </inertial>
        <collision name='collision'>
          <geometry>
            <cylinder>
              <radius>0.32</radius>
              <length>0.23</length>
            </cylinder>
          </geometry>
          <max_contacts>1</max_contacts>
          <surface>
            <friction>
              <ode>
                <mu>1</mu>
                <mu2>1</mu2>
                <fdir1>0 0 1</fdir1>
                <slip1>0</slip1>
                <slip2>0</slip2>
              </ode>
              <torsional>
                <ode/>
              </torsional>
            </friction>
            <contact>
              <ode>
                <min_depth>0.005</min_depth>
                <kp>1e+08</kp>
              </ode>
            </contact>
            <bounce/>
          </surface>
        </collision>
        <visual name='visual'>
          <pose>0 0 0 3.14159 -1.57079 3.14159</pose>
          <geometry>
            <mesh>
              <uri>model://polaris_ranger_ev/meshes/polaris.dae</uri>
              <submesh>
                <name>Rear_Wheel_Right</name>
                <center>1</center>
              </submesh>
            </mesh>
          </geometry>
          <material>
            <script>
              <uri>model://polaris_ranger_ev/materials/scripts</uri>
              <uri>model://polaris_ranger_ev/materials/textures</uri>
              <name>Polaris/Diffuse</name>
            </script>
          </material>
        </visual>
        <self_collide>0</self_collide>
        <enable_wind>0</enable_wind>
        <kinematic>0</kinematic>
      </link>
      <link name='rear_left_wheel'>
        <pose>-0.85 0.6 0.32 -1.52 0 0</pose>
        <inertial>
          <mass>12</mass>
          <inertia>
            <ixx>0.5</ixx>
            <ixy>0</ixy>
            <iyy>0.5</iyy>
            <ixz>0</ixz>
            <iyz>0</iyz>
            <izz>1</izz>
          </inertia>
          <pose>0 0 0 0 -0 0</pose>
        </inertial>
        <collision name='collision'>
          <geometry>
            <cylinder>
              <radius>0.32</radius>
              <length>0.23</length>
            </cylinder>
          </geometry>
          <max_contacts>1</max_contacts>
          <surface>
            <friction>
              <ode>
                <mu>1</mu>
                <mu2>1</mu2>
                <fdir1>0 0 1</fdir1>
                <slip1>0</slip1>
                <slip2>0</slip2>
              </ode>
              <torsional>
                <ode/>
              </torsional>
            </friction>
            <contact>
              <ode>
                <min_depth>0.005</min_depth>
                <kp>1e+08</kp>
              </ode>
            </contact>
            <bounce/>
          </surface>
        </collision>
        <visual name='visual'>
          <pose>0 0 0 3.14159 -1.57079 3.14159</pose>
          <geometry>
            <mesh>
              <uri>model://polaris_ranger_ev/meshes/polaris.dae</uri>
              <submesh>
                <name>Rear_Wheel_Left</name>
                <center>1</center>
              </submesh>
            </mesh>
          </geometry>
          <material>
            <script>
              <uri>model://polaris_ranger_ev/materials/scripts</uri>
              <uri>model://polaris_ranger_ev/materials/textures</uri>
              <name>Polaris/Diffuse</name>
            </script>
          </material>
        </visual>
        <self_collide>0</self_collide>
        <enable_wind>0</enable_wind>
        <kinematic>0</kinematic>
      </link>
      <link name='front_right_wheel'>
        <pose>1.03 -0.6 0.32 1.52 -0 0</pose>
        <inertial>
          <mass>12</mass>
          <inertia>
            <ixx>0.5</ixx>
            <ixy>0</ixy>
            <iyy>0.5</iyy>
            <ixz>0</ixz>
            <iyz>0</iyz>
            <izz>1</izz>
          </inertia>
          <pose>0 0 0 0 -0 0</pose>
        </inertial>
        <collision name='collision'>
          <geometry>
            <cylinder>
              <radius>0.32</radius>
              <length>0.23</length>
            </cylinder>
          </geometry>
          <max_contacts>1</max_contacts>
          <surface>
            <friction>
              <ode>
                <mu>1</mu>
                <mu2>1</mu2>
                <fdir1>0 0 1</fdir1>
                <slip1>0</slip1>
                <slip2>0</slip2>
              </ode>
              <torsional>
                <ode/>
              </torsional>
            </friction>
            <contact>
              <ode>
                <min_depth>0.005</min_depth>
                <kp>1e+08</kp>
              </ode>
            </contact>
            <bounce/>
          </surface>
        </collision>
        <visual name='visual'>
          <pose>0 0 0 3.14159 -1.57079 3.14159</pose>
          <geometry>
            <mesh>
              <uri>model://polaris_ranger_ev/meshes/polaris.dae</uri>
              <submesh>
                <name>Front_Wheel_Right</name>
                <center>1</center>
              </submesh>
            </mesh>
          </geometry>
          <material>
            <script>
              <uri>model://polaris_ranger_ev/materials/scripts</uri>
              <uri>model://polaris_ranger_ev/materials/textures</uri>
              <name>Polaris/Diffuse</name>
            </script>
          </material>
        </visual>
        <self_collide>0</self_collide>
        <enable_wind>0</enable_wind>
        <kinematic>0</kinematic>
      </link>
      <link name='front_right_wheel_steering_block'>
        <pose>1.03 -0.5 0.32 1.5708 -0 0</pose>
        <inertial>
          <mass>1</mass>
          <inertia>
            <ixx>1</ixx>
            <ixy>0</ixy>
            <iyy>1</iyy>
            <ixz>0</ixz>
            <iyz>0</iyz>
            <izz>1</izz>
          </inertia>
          <pose>0 0 0 0 -0 0</pose>
        </inertial>
        <collision name='collision'>
          <geometry>
            <cylinder>
              <radius>0.05</radius>
              <length>0.01</length>
            </cylinder>
          </geometry>
          <max_contacts>10</max_contacts>
          <surface>
            <contact>
              <ode/>
            </contact>
            <bounce/>
            <friction>
              <torsional>
                <ode/>
              </torsional>
              <ode/>
            </friction>
          </surface>
        </collision>
        <self_collide>0</self_collide>
        <enable_wind>0</enable_wind>
        <kinematic>0</kinematic>
      </link>
      <link name='front_left_wheel'>
        <pose>1.03 0.6 0.32 -1.52 0 0</pose>
        <inertial>
          <mass>12</mass>
          <inertia>
            <ixx>0.5</ixx>
            <ixy>0</ixy>
            <iyy>0.5</iyy>
            <ixz>0</ixz>
            <iyz>0</iyz>
            <izz>1</izz>
          </inertia>
          <pose>0 0 0 0 -0 0</pose>
        </inertial>
        <collision name='collision'>
          <geometry>
            <cylinder>
              <radius>0.32</radius>
              <length>0.23</length>
            </cylinder>
          </geometry>
          <max_contacts>1</max_contacts>
          <surface>
            <friction>
              <ode>
                <mu>1</mu>
                <mu2>1</mu2>
                <fdir1>0 0 1</fdir1>
                <slip1>0</slip1>
                <slip2>0</slip2>
              </ode>
              <torsional>
                <ode/>
              </torsional>
            </friction>
            <contact>
              <ode>
                <min_depth>0.005</min_depth>
                <kp>1e+08</kp>
              </ode>
            </contact>
            <bounce/>
          </surface>
        </collision>
        <visual name='visual'>
          <pose>0 0 0 -3e-06 1.57079 3.14159</pose>
          <geometry>
            <mesh>
              <uri>model://polaris_ranger_ev/meshes/polaris.dae</uri>
              <submesh>
                <name>Front_Wheel_Left</name>
                <center>1</center>
              </submesh>
            </mesh>
          </geometry>
          <material>
            <script>
              <uri>model://polaris_ranger_ev/materials/scripts</uri>
              <uri>model://polaris_ranger_ev/materials/textures</uri>
              <name>Polaris/Diffuse</name>
            </script>
          </material>
        </visual>
        <self_collide>0</self_collide>
        <enable_wind>0</enable_wind>
        <kinematic>0</kinematic>
      </link>
      <link name='front_left_wheel_steering_block'>
        <pose>1.03 0.5 0.32 1.5708 -0 0</pose>
        <inertial>
          <mass>1</mass>
          <inertia>
            <ixx>1</ixx>
            <ixy>0</ixy>
            <iyy>1</iyy>
            <ixz>0</ixz>
            <iyz>0</iyz>
            <izz>1</izz>
          </inertia>
          <pose>0 0 0 0 -0 0</pose>
        </inertial>
        <collision name='collision'>
          <geometry>
            <cylinder>
              <radius>0.05</radius>
              <length>0.01</length>
            </cylinder>
          </geometry>
          <max_contacts>10</max_contacts>
          <surface>
            <contact>
              <ode/>
            </contact>
            <bounce/>
            <friction>
              <torsional>
                <ode/>
              </torsional>
              <ode/>
            </friction>
          </surface>
        </collision>
        <self_collide>0</self_collide>
        <enable_wind>0</enable_wind>
        <kinematic>0</kinematic>
      </link>
      <link name='gas_pedal'>
        <pose>0.63 0.1 0.58 0 -0 0</pose>
        <gravity>0</gravity>
        <inertial>
          <mass>0.1</mass>
          <pose>0 0 0 0 -0 0</pose>
          <inertia>
            <ixx>0.01</ixx>
            <ixy>0</ixy>
            <ixz>0</ixz>
            <iyy>0.01</iyy>
            <iyz>0</iyz>
            <izz>0.01</izz>
          </inertia>
        </inertial>
        <collision name='gas_pedal_collision'>
          <pose>-0.0385 0 -0.086 3.14159 1.12559 3.14159</pose>
          <geometry>
            <box>
              <size>0.1069 0.077 0.01</size>
            </box>
          </geometry>
          <max_contacts>10</max_contacts>
          <surface>
            <contact>
              <ode/>
            </contact>
            <bounce/>
            <friction>
              <torsional>
                <ode/>
              </torsional>
              <ode/>
            </friction>
          </surface>
        </collision>
        <visual name='visual'>
          <pose>0 0 0 0 0 -1.5707</pose>
          <geometry>
            <mesh>
              <uri>model://polaris_ranger_ev/meshes/polaris.dae</uri>
              <submesh>
                <name>Pedal_Gas</name>
                <center>1</center>
              </submesh>
            </mesh>
          </geometry>
          <material>
            <script>
              <uri>model://polaris_ranger_ev/materials/scripts</uri>
              <uri>model://polaris_ranger_ev/materials/textures</uri>
              <name>Polaris/Diffuse</name>
            </script>
          </material>
        </visual>
        <self_collide>0</self_collide>
        <enable_wind>0</enable_wind>
        <kinematic>0</kinematic>
      </link>
      <link name='brake_pedal'>
        <gravity>0</gravity>
        <pose>0.64 0.27 0.58 0 -0 0</pose>
        <inertial>
          <mass>0.1</mass>
          <pose>0 0 0 0 -0 0</pose>
          <inertia>
            <ixx>0.01</ixx>
            <ixy>0</ixy>
            <ixz>0</ixz>
            <iyy>0.01</iyy>
            <iyz>0</iyz>
            <izz>0.01</izz>
          </inertia>
        </inertial>
        <collision name='brake_pedal_collision'>
          <pose>-0.04 0 -0.086 3.14159 1.14259 3.14159</pose>
          <geometry>
            <box>
              <size>0.063 0.08 0.01</size>
            </box>
          </geometry>
          <max_contacts>10</max_contacts>
          <surface>
            <contact>
              <ode/>
            </contact>
            <bounce/>
            <friction>
              <torsional>
                <ode/>
              </torsional>
              <ode/>
            </friction>
          </surface>
        </collision>
        <visual name='visual'>
          <pose>0 0 0 0 0 -1.5707</pose>
          <geometry>
            <mesh>
              <uri>model://polaris_ranger_ev/meshes/polaris.dae</uri>
              <submesh>
                <name>Pedal_brake</name>
                <center>1</center>
              </submesh>
            </mesh>
          </geometry>
          <material>
            <script>
              <uri>model://polaris_ranger_ev/materials/scripts</uri>
              <uri>model://polaris_ranger_ev/materials/textures</uri>
              <name>Polaris/Diffuse</name>
            </script>
          </material>
        </visual>
        <self_collide>0</self_collide>
        <enable_wind>0</enable_wind>
        <kinematic>0</kinematic>
      </link>
      <link name='steering_wheel'>
        <pose>0.34 0.3 1.29 0 -0.87 0</pose>
        <inertial>
          <mass>1</mass>
          <pose>-0.002 0 0 0 -0 0</pose>
          <inertia>
            <ixx>0.012</ixx>
            <ixy>0</ixy>
            <ixz>0</ixz>
            <iyy>0.012</iyy>
            <iyz>0</iyz>
            <izz>0.024</izz>
          </inertia>
        </inertial>
        <collision name='collision'>
          <pose>0 0 0 -0.69 -0 -1.5708</pose>
          <geometry>
            <mesh>
              <uri>model://polaris_ranger_ev/meshes/polaris.dae</uri>
              <submesh>
                <name>Steering_Wheel</name>
                <center>1</center>
              </submesh>
            </mesh>
          </geometry>
          <surface>
            <contact>
              <ode>
                <min_depth>0.003</min_depth>
              </ode>
            </contact>
            <bounce/>
            <friction>
              <torsional>
                <ode/>
              </torsional>
              <ode/>
            </friction>
          </surface>
          <max_contacts>10</max_contacts>
        </collision>
        <visual name='visual'>
          <pose>0 0 0 -0.69 -0 -1.5708</pose>
          <geometry>
            <mesh>
              <uri>model://polaris_ranger_ev/meshes/polaris.dae</uri>
              <submesh>
                <name>Steering_Wheel</name>
                <center>1</center>
              </submesh>
            </mesh>
          </geometry>
          <material>
            <script>
              <uri>model://polaris_ranger_ev/materials/scripts</uri>
              <uri>model://polaris_ranger_ev/materials/textures</uri>
              <name>Polaris/Diffuse</name>
            </script>
          </material>
        </visual>
        <self_collide>0</self_collide>
        <enable_wind>0</enable_wind>
        <kinematic>0</kinematic>
      </link>
      <link name='hand_brake'>
        <pose>0.53 0.07 1.05 0 -0 0</pose>
        <inertial>
          <mass>0.5</mass>
          <inertia>
            <ixx>0.1</ixx>
            <ixy>0</ixy>
            <ixz>0</ixz>
            <iyy>0.1</iyy>
            <iyz>0</iyz>
            <izz>0.05</izz>
          </inertia>
          <pose>0 0 0 0 -0 0</pose>
        </inertial>
        <collision name='hand_brake_collision'>
          <pose>0 0 0.05 -0.2 -0 -1.5708</pose>
          <geometry>
            <mesh>
              <uri>model://polaris_ranger_ev/meshes/polaris.dae</uri>
              <submesh>
                <name>E-Brake</name>
                <center>1</center>
              </submesh>
            </mesh>
          </geometry>
          <max_contacts>10</max_contacts>
          <surface>
            <contact>
              <ode/>
            </contact>
            <bounce/>
            <friction>
              <torsional>
                <ode/>
              </torsional>
              <ode/>
            </friction>
          </surface>
        </collision>
        <visual name='hand_brake_visual'>
          <pose>0 0 0.05 -0.2 -0 -1.5708</pose>
          <geometry>
            <mesh>
              <uri>model://polaris_ranger_ev/meshes/polaris.dae</uri>
              <submesh>
                <name>E-Brake</name>
                <center>1</center>
              </submesh>
            </mesh>
          </geometry>
          <material>
            <script>
              <uri>model://polaris_ranger_ev/materials/scripts</uri>
              <uri>model://polaris_ranger_ev/materials/textures</uri>
              <name>Polaris/Diffuse</name>
            </script>
          </material>
        </visual>
        <self_collide>0</self_collide>
        <enable_wind>0</enable_wind>
        <kinematic>0</kinematic>
      </link>
      <link name='FNR_switch'>
        <pose>0.56 -0.02 1.08 0 0.25 0</pose>
        <inertial>
          <mass>0.1</mass>
          <inertia>
            <ixx>0.1</ixx>
            <ixy>0</ixy>
            <ixz>0</ixz>
            <iyy>6e-05</iyy>
            <iyz>0</iyz>
            <izz>0.1</izz>
          </inertia>
          <pose>0 0 0 0 -0 0</pose>
        </inertial>
        <collision name='FNR_switch'>
          <geometry>
            <box>
              <size>0.02 0.04 0.08</size>
            </box>
          </geometry>
          <max_contacts>10</max_contacts>
          <surface>
            <contact>
              <ode/>
            </contact>
            <bounce/>
            <friction>
              <torsional>
                <ode/>
              </torsional>
              <ode/>
            </friction>
          </surface>
        </collision>
        <visual name='FNR_switch_F'>
          <transparency>0</transparency>
          <geometry>
            <box>
              <size>0.02 0.04 0.08</size>
            </box>
          </geometry>
          <material>
            <script>
              <uri>model://polaris_ranger_ev/materials/scripts</uri>
              <uri>model://polaris_ranger_ev/materials/textures</uri>
              <name>FNR_switch_F</name>
            </script>
          </material>
        </visual>
        <visual name='FNR_switch_R'>
          <transparency>1</transparency>
          <geometry>
            <box>
              <size>0.0199 0.0399 0.0799</size>
            </box>
          </geometry>
          <material>
            <script>
              <uri>model://polaris_ranger_ev/materials/scripts</uri>
              <uri>model://polaris_ranger_ev/materials/textures</uri>
              <name>FNR_switch_R</name>
            </script>
          </material>
        </visual>
        <self_collide>0</self_collide>
        <enable_wind>0</enable_wind>
        <kinematic>0</kinematic>
      </link>
      <joint name='front_left_steering_joint' type='revolute'>
        <child>front_left_wheel_steering_block</child>
        <parent>chassis</parent>
        <axis>
          <xyz expressed_in='__model__'>0 0 1</xyz>
          <limit>
            <lower>-0.8727</lower>
            <upper>0.8727</upper>
          </limit>
          <dynamics>
            <damping>50</damping>
            <spring_reference>0</spring_reference>
            <spring_stiffness>0</spring_stiffness>
          </dynamics>
        </axis>
        <physics>
          <ode>
            <cfm_damping>1</cfm_damping>
            <limit>
              <cfm>0</cfm>
              <erp>0.9</erp>
            </limit>
          </ode>
        </physics>
      </joint>
      <joint name='front_left_wheel_joint' type='revolute'>
        <child>front_left_wheel</child>
        <parent>front_left_wheel_steering_block</parent>
        <axis>
          <xyz expressed_in='__model__'>0 1 0.05</xyz>
          <limit>
            <lower>-1e+16</lower>
            <upper>1e+16</upper>
          </limit>
          <dynamics>
            <spring_reference>0</spring_reference>
            <spring_stiffness>0</spring_stiffness>
          </dynamics>
        </axis>
      </joint>
      <joint name='front_right_steering_joint' type='revolute'>
        <child>front_right_wheel_steering_block</child>
        <parent>chassis</parent>
        <axis>
          <xyz expressed_in='__model__'>0 0 1</xyz>
          <limit>
            <lower>-0.8727</lower>
            <upper>0.8727</upper>
          </limit>
          <dynamics>
            <damping>50</damping>
            <spring_reference>0</spring_reference>
            <spring_stiffness>0</spring_stiffness>
          </dynamics>
        </axis>
        <physics>
          <ode>
            <cfm_damping>1</cfm_damping>
            <limit>
              <cfm>0</cfm>
              <erp>0.9</erp>
            </limit>
          </ode>
        </physics>
      </joint>
      <joint name='front_right_wheel_joint' type='revolute'>
        <child>front_right_wheel</child>
        <parent>front_right_wheel_steering_block</parent>
        <axis>
          <xyz expressed_in='__model__'>0 1 -0.05</xyz>
          <limit>
            <lower>-1e+16</lower>
            <upper>1e+16</upper>
          </limit>
          <dynamics>
            <spring_reference>0</spring_reference>
            <spring_stiffness>0</spring_stiffness>
          </dynamics>
        </axis>
      </joint>
      <joint name='rear_left_wheel_joint' type='revolute'>
        <child>rear_left_wheel</child>
        <parent>chassis</parent>
        <axis>
          <xyz expressed_in='__model__'>0 1 0.05</xyz>
          <limit>
            <lower>-1e+16</lower>
            <upper>1e+16</upper>
          </limit>
          <dynamics>
            <spring_reference>0</spring_reference>
            <spring_stiffness>0</spring_stiffness>
          </dynamics>
        </axis>
      </joint>
      <joint name='rear_right_wheel_joint' type='revolute'>
        <pose>0 0 -0.1 0 -0 0</pose>
        <child>rear_right_wheel</child>
        <parent>chassis</parent>
        <axis>
          <xyz expressed_in='__model__'>0 1 -0.05</xyz>
          <limit>
            <lower>-1e+16</lower>
            <upper>1e+16</upper>
          </limit>
          <dynamics>
            <spring_reference>0</spring_reference>
            <spring_stiffness>0</spring_stiffness>
          </dynamics>
        </axis>
      </joint>
      <joint name='rear_differential_joint' type='revolute'>
        <child>rear_right_wheel</child>
        <parent>rear_left_wheel</parent>
        <axis>
          <xyz expressed_in='__model__'>0 1 0</xyz>
          <dynamics>
            <damping>70</damping>
            <spring_reference>0</spring_reference>
            <spring_stiffness>0</spring_stiffness>
          </dynamics>
          <limit>
            <lower>-1e+16</lower>
            <upper>1e+16</upper>
          </limit>
        </axis>
        <physics>
          <ode>
            <erp>0</erp>
            <cfm>1000</cfm>
            <cfm_damping>1</cfm_damping>
            <limit>
              <cfm>0</cfm>
              <erp>0.2</erp>
            </limit>
          </ode>
        </physics>
      </joint>
      <joint name='gas_joint' type='prismatic'>
        <parent>chassis</parent>
        <child>gas_pedal</child>
        <axis>
          <xyz expressed_in='__model__'>1 0 -1</xyz>
          <limit>
            <lower>0</lower>
            <upper>0.08</upper>
          </limit>
          <dynamics>
            <damping>3</damping>
            <spring_reference>0</spring_reference>
            <spring_stiffness>0</spring_stiffness>
          </dynamics>
        </axis>
        <physics>
          <ode>
            <cfm_damping>1</cfm_damping>
            <limit>
              <cfm>0</cfm>
              <erp>0.2</erp>
            </limit>
          </ode>
        </physics>
      </joint>
      <joint name='brake_joint' type='prismatic'>
        <parent>chassis</parent>
        <child>brake_pedal</child>
        <axis>
          <xyz expressed_in='__model__'>1 0 -0.6</xyz>
          <limit>
            <lower>0</lower>
            <upper>0.08</upper>
          </limit>
          <dynamics>
            <damping>3</damping>
            <spring_reference>0</spring_reference>
            <spring_stiffness>0</spring_stiffness>
          </dynamics>
        </axis>
        <physics>
          <ode>
            <cfm_damping>1</cfm_damping>
            <limit>
              <cfm>0</cfm>
              <erp>0.2</erp>
            </limit>
          </ode>
        </physics>
      </joint>
      <joint name='steering_joint' type='revolute'>
        <pose>-0.002 0 0 0 -0 0</pose>
        <parent>chassis</parent>
        <child>steering_wheel</child>
        <axis>
          <xyz expressed_in='__model__'>-1 0 0.84365</xyz>
          <limit>
            <lower>-3.14</lower>
            <upper>3.14</upper>
          </limit>
          <dynamics>
            <damping>1</damping>
            <spring_reference>0</spring_reference>
            <spring_stiffness>0</spring_stiffness>
          </dynamics>
        </axis>
        <physics>
          <ode>
            <cfm_damping>1</cfm_damping>
            <limit>
              <cfm>0</cfm>
              <erp>0.2</erp>
            </limit>
          </ode>
        </physics>
      </joint>
      <joint name='hand_brake_joint' type='revolute'>
        <parent>chassis</parent>
        <child>hand_brake</child>
        <axis>
          <xyz expressed_in='__model__'>0 -1 0</xyz>
          <limit>
            <lower>0</lower>
            <upper>0.6</upper>
          </limit>
          <dynamics>
            <damping>1</damping>
            <spring_reference>0</spring_reference>
            <spring_stiffness>0</spring_stiffness>
          </dynamics>
        </axis>
        <physics>
          <ode>
            <cfm_damping>1</cfm_damping>
            <limit>
              <cfm>0</cfm>
              <erp>0.2</erp>
            </limit>
          </ode>
        </physics>
      </joint>
      <joint name='FNR_switch_joint' type='revolute'>
        <parent>chassis</parent>
        <child>FNR_switch</child>
        <axis>
          <xyz expressed_in='__model__'>0 -1 0</xyz>
          <limit>
            <lower>-0.3</lower>
            <upper>0.3</upper>
          </limit>
          <dynamics>
            <damping>0.01</damping>
            <spring_reference>0</spring_reference>
            <spring_stiffness>0</spring_stiffness>
          </dynamics>
        </axis>
        <physics>
          <ode>
            <cfm_damping>1</cfm_damping>
            <limit>
              <cfm>0</cfm>
              <erp>0.2</erp>
            </limit>
          </ode>
        </physics>
      </joint>
      <pose>-2.47882 2.59356 0 0 -0 0</pose>
    </model>
    <model name='postbox'>
      <static>1</static>
      <link name='link'>
        <collision name='collision'>
          <geometry>
            <mesh>
              <uri>model://postbox/meshes/postbox.dae</uri>
            </mesh>
          </geometry>
          <max_contacts>10</max_contacts>
          <surface>
            <contact>
              <ode/>
            </contact>
            <bounce/>
            <friction>
              <torsional>
                <ode/>
              </torsional>
              <ode/>
            </friction>
          </surface>
        </collision>
        <visual name='visual'>
          <geometry>
            <mesh>
              <uri>model://postbox/meshes/postbox.dae</uri>
            </mesh>
          </geometry>
        </visual>
        <self_collide>0</self_collide>
        <enable_wind>0</enable_wind>
        <kinematic>0</kinematic>
      </link>
      <pose>2.03099 2.66028 0 0 -0 0</pose>
    </model>
    <model name='husky'>
      <pose>3.8074 -2.92779 0.5 0 -0 0</pose>
      <link name='base_link'>
        <collision name='collision'>
          <pose>0 0 0.1 0 -0 0</pose>
          <geometry>
            <box>
              <size>1.0074 0.5709 0.2675</size>
            </box>
          </geometry>
          <max_contacts>10</max_contacts>
          <surface>
            <contact>
              <ode/>
            </contact>
            <bounce/>
            <friction>
              <torsional>
                <ode/>
              </torsional>
              <ode/>
            </friction>
          </surface>
        </collision>
        <inertial>
          <mass>33.855</mass>
          <pose>-0.085613 -0.00084 0.238145 0 -0 0</pose>
          <inertia>
            <ixx>2.2343</ixx>
            <ixy>-0.023642</ixy>
            <ixz>0.275174</ixz>
            <iyy>3.42518</iyy>
            <iyz>0.00239624</iyz>
            <izz>2.1241</izz>
          </inertia>
        </inertial>
        <visual name='base'>
          <pose>0 0 0 0 -0 0</pose>
          <geometry>
            <mesh>
              <uri>model://husky/meshes/base_link.stl</uri>
            </mesh>
          </geometry>
          <material>
            <script>
              <name>Gazebo/FlatBlack</name>
              <uri>__default__</uri>
            </script>
          </material>
        </visual>
        <visual name='top_plate'>
          <pose>0 0 0 0 -0 0</pose>
          <geometry>
            <mesh>
              <uri>model://husky/meshes/top_plate.stl</uri>
            </mesh>
          </geometry>
          <material>
            <script>
              <name>Gazebo/Yellow</name>
              <uri>__default__</uri>
            </script>
          </material>
        </visual>
        <visual name='front_bumper'>
          <pose>0.47 0 0.091 0 -0 0</pose>
          <geometry>
            <mesh>
              <uri>model://husky/meshes/bumper.stl</uri>
            </mesh>
          </geometry>
          <material>
            <script>
              <name>Gazebo/FlatBlack</name>
              <uri>__default__</uri>
            </script>
          </material>
        </visual>
        <visual name='rear_bumper'>
          <pose>-0.47 0 0.091 0 -0 3.141</pose>
          <geometry>
            <mesh>
              <uri>model://husky/meshes/bumper.stl</uri>
            </mesh>
          </geometry>
          <material>
            <script>
              <name>Gazebo/FlatBlack</name>
              <uri>__default__</uri>
            </script>
          </material>
        </visual>
        <visual name='user_rail'>
          <pose>0.272 0 0.245 0 -0 0</pose>
          <geometry>
            <mesh>
              <uri>model://husky/meshes/user_rail.stl</uri>
            </mesh>
          </geometry>
          <material>
            <script>
              <name>Gazebo/Grey</name>
              <uri>__default__</uri>
            </script>
          </material>
        </visual>
        <self_collide>0</self_collide>
        <enable_wind>0</enable_wind>
        <kinematic>0</kinematic>
      </link>
      <link name='back_left_wheel'>
        <pose>-0.256 0.285475 0.035 0 -0 0</pose>
        <inertial>
          <mass>2.6357</mass>
          <pose>0 0 0 0 -0 0</pose>
          <inertia>
            <ixx>0.0246688</ixx>
            <ixy>0</ixy>
            <ixz>0</ixz>
            <iyy>0.0246688</iyy>
            <iyz>0</iyz>
            <izz>0.0441058</izz>
          </inertia>
        </inertial>
        <collision name='back_left_wheel_collision'>
          <pose>0 0 0 -1.5707 0 0</pose>
          <geometry>
            <cylinder>
              <radius>0.17775</radius>
              <length>0.1143</length>
            </cylinder>
          </geometry>
          <surface>
            <friction>
              <ode>
                <mu>100000</mu>
                <mu2>100000</mu2>
                <slip1>0</slip1>
                <slip2>0</slip2>
              </ode>
              <torsional>
                <ode/>
              </torsional>
            </friction>
            <contact>
              <ode/>
            </contact>
            <bounce/>
          </surface>
          <max_contacts>10</max_contacts>
        </collision>
        <visual name='back_left_wheel'>
          <pose>0 0 0 -3.14159 0 0</pose>
          <geometry>
            <mesh>
              <uri>model://husky/meshes/wheel.stl</uri>
            </mesh>
          </geometry>
          <material>
            <script>
              <name>Gazebo/Grey</name>
              <uri>__default__</uri>
            </script>
          </material>
        </visual>
        <self_collide>0</self_collide>
        <enable_wind>0</enable_wind>
        <kinematic>0</kinematic>
      </link>
      <joint name='back_left_joint' type='revolute'>
        <parent>base_link</parent>
        <child>back_left_wheel</child>
        <axis>
          <xyz expressed_in='__model__'>0 1 0</xyz>
          <limit>
            <lower>-1e+16</lower>
            <upper>1e+16</upper>
          </limit>
          <dynamics>
            <spring_reference>0</spring_reference>
            <spring_stiffness>0</spring_stiffness>
          </dynamics>
        </axis>
        <physics>
          <ode>
            <limit>
              <cfm>0</cfm>
              <erp>0.9</erp>
            </limit>
          </ode>
        </physics>
      </joint>
      <link name='back_right_wheel'>
        <pose>-0.256 -0.285475 0.035 0 -0 0</pose>
        <inertial>
          <mass>2.6357</mass>
          <pose>0 0 0 0 -0 0</pose>
          <inertia>
            <ixx>0.0246688</ixx>
            <ixy>0</ixy>
            <ixz>0</ixz>
            <iyy>0.0246688</iyy>
            <iyz>0</iyz>
            <izz>0.0441058</izz>
          </inertia>
        </inertial>
        <collision name='back_right_wheel_collision'>
          <pose>0 0 0 -1.5707 0 0</pose>
          <geometry>
            <cylinder>
              <radius>0.17775</radius>
              <length>0.1143</length>
            </cylinder>
          </geometry>
          <surface>
            <friction>
              <ode>
                <mu>100000</mu>
                <mu2>100000</mu2>
                <slip1>0</slip1>
                <slip2>0</slip2>
              </ode>
              <torsional>
                <ode/>
              </torsional>
            </friction>
            <contact>
              <ode/>
            </contact>
            <bounce/>
          </surface>
          <max_contacts>10</max_contacts>
        </collision>
        <visual name='back_right_wheel'>
          <pose>0 0 0 -3.14159 0 0</pose>
          <geometry>
            <mesh>
              <uri>model://husky/meshes/wheel.stl</uri>
            </mesh>
          </geometry>
          <material>
            <script>
              <name>Gazebo/Grey</name>
              <uri>__default__</uri>
            </script>
          </material>
        </visual>
        <self_collide>0</self_collide>
        <enable_wind>0</enable_wind>
        <kinematic>0</kinematic>
      </link>
      <joint name='back_right_joint' type='revolute'>
        <parent>base_link</parent>
        <child>back_right_wheel</child>
        <axis>
          <xyz expressed_in='__model__'>0 1 0</xyz>
          <limit>
            <lower>-1e+16</lower>
            <upper>1e+16</upper>
          </limit>
          <dynamics>
            <spring_reference>0</spring_reference>
            <spring_stiffness>0</spring_stiffness>
          </dynamics>
        </axis>
        <physics>
          <ode>
            <limit>
              <cfm>0</cfm>
              <erp>0.9</erp>
            </limit>
          </ode>
        </physics>
      </joint>
      <link name='front_left_wheel'>
        <pose>0.256 0.285475 0.035 0 -0 0</pose>
        <inertial>
          <mass>2.6357</mass>
          <pose>0 0 0 0 -0 0</pose>
          <inertia>
            <ixx>0.0246688</ixx>
            <ixy>0</ixy>
            <ixz>0</ixz>
            <iyy>0.0246688</iyy>
            <iyz>0</iyz>
            <izz>0.0441058</izz>
          </inertia>
        </inertial>
        <collision name='front_left_wheel_collision'>
          <pose>0 0 0 -1.5707 0 0</pose>
          <geometry>
            <cylinder>
              <radius>0.17775</radius>
              <length>0.1143</length>
            </cylinder>
          </geometry>
          <surface>
            <friction>
              <ode>
                <mu>100000</mu>
                <mu2>100000</mu2>
                <slip1>0</slip1>
                <slip2>0</slip2>
              </ode>
              <torsional>
                <ode/>
              </torsional>
            </friction>
            <contact>
              <ode/>
            </contact>
            <bounce/>
          </surface>
          <max_contacts>10</max_contacts>
        </collision>
        <visual name='front_left_wheel'>
          <pose>0 0 0 -3.14159 0 0</pose>
          <geometry>
            <mesh>
              <uri>model://husky/meshes/wheel.stl</uri>
            </mesh>
          </geometry>
          <material>
            <script>
              <name>Gazebo/Grey</name>
              <uri>__default__</uri>
            </script>
          </material>
        </visual>
        <self_collide>0</self_collide>
        <enable_wind>0</enable_wind>
        <kinematic>0</kinematic>
      </link>
      <joint name='front_left_joint' type='revolute'>
        <parent>base_link</parent>
        <child>front_left_wheel</child>
        <axis>
          <xyz expressed_in='__model__'>0 1 0</xyz>
          <limit>
            <lower>-1e+16</lower>
            <upper>1e+16</upper>
          </limit>
          <dynamics>
            <spring_reference>0</spring_reference>
            <spring_stiffness>0</spring_stiffness>
          </dynamics>
        </axis>
        <physics>
          <ode>
            <limit>
              <cfm>0</cfm>
              <erp>0.9</erp>
            </limit>
          </ode>
        </physics>
      </joint>
      <link name='front_right_wheel'>
        <pose>0.256 -0.285475 0.035 0 -0 0</pose>
        <inertial>
          <mass>2.6357</mass>
          <pose>0 0 0 0 -0 0</pose>
          <inertia>
            <ixx>0.0246688</ixx>
            <ixy>0</ixy>
            <ixz>0</ixz>
            <iyy>0.0246688</iyy>
            <iyz>0</iyz>
            <izz>0.0441058</izz>
          </inertia>
        </inertial>
        <collision name='front_right_wheel_collision'>
          <pose>0 0 0 -1.5707 0 0</pose>
          <geometry>
            <cylinder>
              <radius>0.17775</radius>
              <length>0.1143</length>
            </cylinder>
          </geometry>
          <surface>
            <friction>
              <ode>
                <mu>100000</mu>
                <mu2>100000</mu2>
                <slip1>0</slip1>
                <slip2>0</slip2>
              </ode>
              <torsional>
                <ode/>
              </torsional>
            </friction>
            <contact>
              <ode/>
            </contact>
            <bounce/>
          </surface>
          <max_contacts>10</max_contacts>
        </collision>
        <visual name='front_right_wheel'>
          <pose>0 0 0 -3.14159 0 0</pose>
          <geometry>
            <mesh>
              <uri>model://husky/meshes/wheel.stl</uri>
            </mesh>
          </geometry>
          <material>
            <script>
              <name>Gazebo/Grey</name>
              <uri>__default__</uri>
            </script>
          </material>
        </visual>
        <self_collide>0</self_collide>
        <enable_wind>0</enable_wind>
        <kinematic>0</kinematic>
      </link>
      <joint name='front_right_joint' type='revolute'>
        <parent>base_link</parent>
        <child>front_right_wheel</child>
        <axis>
          <xyz expressed_in='__model__'>0 1 0</xyz>
          <limit>
            <lower>-1e+16</lower>
            <upper>1e+16</upper>
          </limit>
          <dynamics>
            <spring_reference>0</spring_reference>
            <spring_stiffness>0</spring_stiffness>
          </dynamics>
        </axis>
        <physics>
          <ode>
            <limit>
              <cfm>0</cfm>
              <erp>0.9</erp>
            </limit>
          </ode>
        </physics>
      </joint>
      <plugin name='husky_diff_controller' filename='libhusky_gazebo_plugins.so'>
        <alwaysOn>1</alwaysOn>
        <updateRate>100.0</updateRate>
        <backLeftJoint>back_left_joint</backLeftJoint>
        <backRightJoint>back_right_joint</backRightJoint>
        <frontLeftJoint>front_left_joint</frontLeftJoint>
        <frontRightJoint>front_right_joint</frontRightJoint>
        <wheelSeparation>0.5709</wheelSeparation>
        <wheelDiameter>0.3555</wheelDiameter>
        <torque>35</torque>
      </plugin>
    </model>
    <model name='cabinet'>
      <static>1</static>
      <link name='cabinet_bottom_plate'>
        <inertial>
          <pose>0 0 -1 0 -0 0</pose>
          <inertia>
            <ixx>2.05</ixx>
            <ixy>0</ixy>
            <ixz>0</ixz>
            <iyy>2.05</iyy>
            <iyz>0</iyz>
            <izz>2.05</izz>
          </inertia>
          <mass>25</mass>
        </inertial>
        <collision name='cabinet_bottom_plate_geom'>
          <pose>0 0 0.01 0 -0 0</pose>
          <geometry>
            <box>
              <size>0.45 0.45 0.02</size>
            </box>
          </geometry>
          <max_contacts>10</max_contacts>
          <surface>
            <contact>
              <ode/>
            </contact>
            <bounce/>
            <friction>
              <torsional>
                <ode/>
              </torsional>
              <ode/>
            </friction>
          </surface>
        </collision>
        <visual name='cabinet_bottom_plate_geom_visual'>
          <pose>0 0 0.01 0 -0 0</pose>
          <geometry>
            <box>
              <size>0.45 0.45 0.02</size>
            </box>
          </geometry>
          <material>
            <script>
              <uri>file://media/materials/scripts/gazebo.material</uri>
              <name>Gazebo/Wood</name>
            </script>
          </material>
        </visual>
        <collision name='cabinet_bottom_plate_geom_cabinet_back_plate'>
          <pose>0.235 0 0.51 0 -0 0</pose>
          <geometry>
            <box>
              <size>0.02 0.45 1.02</size>
            </box>
          </geometry>
          <max_contacts>10</max_contacts>
          <surface>
            <contact>
              <ode/>
            </contact>
            <bounce/>
            <friction>
              <torsional>
                <ode/>
              </torsional>
              <ode/>
            </friction>
          </surface>
        </collision>
        <visual name='cabinet_bottom_plate_geom_cabinet_back_plate_visual'>
          <pose>0.235 0 0.51 0 -0 0</pose>
          <geometry>
            <box>
              <size>0.02 0.45 1.02</size>
            </box>
          </geometry>
          <material>
            <script>
              <uri>file://media/materials/scripts/gazebo.material</uri>
              <name>Gazebo/Wood</name>
            </script>
          </material>
        </visual>
        <collision name='cabinet_bottom_plate_geom_cabinet_left_plate'>
          <pose>0 0.235 0.51 0 -0 0</pose>
          <geometry>
            <box>
              <size>0.45 0.02 1.02</size>
            </box>
          </geometry>
          <max_contacts>10</max_contacts>
          <surface>
            <contact>
              <ode/>
            </contact>
            <bounce/>
            <friction>
              <torsional>
                <ode/>
              </torsional>
              <ode/>
            </friction>
          </surface>
        </collision>
        <visual name='cabinet_bottom_plate_geom_cabinet_left_plate_visual'>
          <pose>0 0.235 0.51 0 -0 0</pose>
          <geometry>
            <box>
              <size>0.45 0.02 1.02</size>
            </box>
          </geometry>
          <material>
            <script>
              <uri>file://media/materials/scripts/gazebo.material</uri>
              <name>Gazebo/Wood</name>
            </script>
          </material>
        </visual>
        <collision name='cabinet_bottom_plate_geom_cabinet_middle_plate'>
          <pose>0 0 0.51 0 -0 0</pose>
          <geometry>
            <box>
              <size>0.45 0.45 0.02</size>
            </box>
          </geometry>
          <max_contacts>10</max_contacts>
          <surface>
            <contact>
              <ode/>
            </contact>
            <bounce/>
            <friction>
              <torsional>
                <ode/>
              </torsional>
              <ode/>
            </friction>
          </surface>
        </collision>
        <visual name='cabinet_bottom_plate_geom_cabinet_middle_plate_visual'>
          <pose>0 0 0.51 0 -0 0</pose>
          <geometry>
            <box>
              <size>0.45 0.45 0.02</size>
            </box>
          </geometry>
          <material>
            <script>
              <uri>file://media/materials/scripts/gazebo.material</uri>
              <name>Gazebo/Wood</name>
            </script>
          </material>
        </visual>
        <collision name='cabinet_bottom_plate_geom_cabinet_right_plate'>
          <pose>0 -0.235 0.51 0 -0 0</pose>
          <geometry>
            <box>
              <size>0.45 0.02 1.02</size>
            </box>
          </geometry>
          <max_contacts>10</max_contacts>
          <surface>
            <contact>
              <ode/>
            </contact>
            <bounce/>
            <friction>
              <torsional>
                <ode/>
              </torsional>
              <ode/>
            </friction>
          </surface>
        </collision>
        <visual name='cabinet_bottom_plate_geom_cabinet_right_plate_visual'>
          <pose>0 -0.235 0.51 0 -0 0</pose>
          <geometry>
            <box>
              <size>0.45 0.02 1.02</size>
            </box>
          </geometry>
          <material>
            <script>
              <uri>file://media/materials/scripts/gazebo.material</uri>
              <name>Gazebo/Wood</name>
            </script>
          </material>
        </visual>
        <collision name='cabinet_bottom_plate_geom_cabinet_top_plate'>
          <pose>0 0 1.01 0 -0 0</pose>
          <geometry>
            <box>
              <size>0.45 0.45 0.02</size>
            </box>
          </geometry>
          <max_contacts>10</max_contacts>
          <surface>
            <contact>
              <ode/>
            </contact>
            <bounce/>
            <friction>
              <torsional>
                <ode/>
              </torsional>
              <ode/>
            </friction>
          </surface>
        </collision>
        <visual name='cabinet_bottom_plate_geom_cabinet_top_plate_visual'>
          <pose>0 0 1.01 0 -0 0</pose>
          <geometry>
            <box>
              <size>0.45 0.45 0.02</size>
            </box>
          </geometry>
          <material>
            <script>
              <uri>file://media/materials/scripts/gazebo.material</uri>
              <name>Gazebo/Wood</name>
            </script>
          </material>
        </visual>
        <self_collide>0</self_collide>
        <enable_wind>0</enable_wind>
        <kinematic>0</kinematic>
      </link>
      <pose>-3.45798 0.156408 0 0 -0 0</pose>
    </model>
    <state world_name='default'>
      <sim_time>133 175000000</sim_time>
      <real_time>133 715622994</real_time>
      <wall_time>1665846893 48814187</wall_time>
      <iterations>133175</iterations>
      <model name='botx_world'>
        <pose>0.323182 -0.055349 0 0 -0 0</pose>
        <scale>1 1 1</scale>
        <link name='Wall_1'>
          <pose>-7.33023 -1.82694 0 0 0 -1.5708</pose>
          <velocity>0 0 0 0 -0 0</velocity>
          <acceleration>0 0 0 0 -0 0</acceleration>
          <wrench>0 0 0 0 -0 0</wrench>
        </link>
        <link name='Wall_10'>
          <pose>6.20279 1.39004 0 0 -0 0</pose>
          <velocity>0 0 0 0 -0 0</velocity>
          <acceleration>0 0 0 0 -0 0</acceleration>
          <wrench>0 0 0 0 -0 0</wrench>
        </link>
        <link name='Wall_11'>
          <pose>7.75279 3.56504 0 0 -0 1.5708</pose>
          <velocity>0 0 0 0 -0 0</velocity>
          <acceleration>0 0 0 0 -0 0</acceleration>
          <wrench>0 0 0 0 -0 0</wrench>
        </link>
        <link name='Wall_12'>
          <pose>3.57779 5.74004 0 0 -0 3.14159</pose>
          <velocity>0 0 0 0 -0 0</velocity>
          <acceleration>0 0 0 0 -0 0</acceleration>
          <wrench>0 0 0 0 -0 0</wrench>
        </link>
        <link name='Wall_13'>
          <pose>-3.96372 3.98155 0 0 0 -2.66023</pose>
          <velocity>0 0 0 0 -0 0</velocity>
          <acceleration>0 0 0 0 -0 0</acceleration>
          <wrench>0 0 0 0 -0 0</wrench>
        </link>
        <link name='Wall_2'>
          <pose>-5.78023 -5.87694 0 0 -0 0</pose>
          <velocity>0 0 0 0 -0 0</velocity>
          <acceleration>0 0 0 0 -0 0</acceleration>
          <wrench>0 0 0 0 -0 0</wrench>
        </link>
        <link name='Wall_3'>
          <pose>-4.23023 -3.82694 0 0 -0 1.5708</pose>
          <velocity>0 0 0 0 -0 0</velocity>
          <acceleration>0 0 0 0 -0 0</acceleration>
          <wrench>0 0 0 0 -0 0</wrench>
        </link>
        <link name='Wall_4'>
          <pose>-2.43023 -1.77694 0 0 -0 0</pose>
          <velocity>0 0 0 0 -0 0</velocity>
          <acceleration>0 0 0 0 -0 0</acceleration>
          <wrench>0 0 0 0 -0 0</wrench>
        </link>
        <link name='Wall_5'>
          <pose>1.26128 -3.66845 0 0 0 -0.785398</pose>
          <velocity>0 0 0 0 -0 0</velocity>
          <acceleration>0 0 0 0 -0 0</acceleration>
          <wrench>0 0 0 0 -0 0</wrench>
        </link>
        <link name='Wall_6'>
          <pose>5.57779 -5.55996 0 0 -0 0</pose>
          <velocity>0 0 0 0 -0 0</velocity>
          <acceleration>0 0 0 0 -0 0</acceleration>
          <wrench>0 0 0 0 -0 0</wrench>
        </link>
        <link name='Wall_7'>
          <pose>8.00279 -2.88496 0 0 -0 1.5708</pose>
          <velocity>0 0 0 0 -0 0</velocity>
          <acceleration>0 0 0 0 -0 0</acceleration>
          <wrench>0 0 0 0 -0 0</wrench>
        </link>
        <link name='Wall_8'>
          <pose>6.32779 -0.20996 0 0 -0 3.14159</pose>
          <velocity>0 0 0 0 -0 0</velocity>
          <acceleration>0 0 0 0 -0 0</acceleration>
          <wrench>0 0 0 0 -0 0</wrench>
        </link>
        <link name='Wall_9'>
          <pose>4.65279 0.59004 0 0 -0 1.5708</pose>
          <velocity>0 0 0 0 -0 0</velocity>
          <acceleration>0 0 0 0 -0 0</acceleration>
          <wrench>0 0 0 0 -0 0</wrench>
        </link>
      </model>
      <model name='cabinet'>
        <pose>-3.45798 0.156408 0 0 -0 0</pose>
        <scale>1 1 1</scale>
        <link name='cabinet_bottom_plate'>
          <pose>-3.45798 0.156408 0 0 -0 0</pose>
          <velocity>0 0 0 0 -0 0</velocity>
          <acceleration>0 0 0 0 -0 0</acceleration>
          <wrench>0 0 0 0 -0 0</wrench>
        </link>
      </model>
      <model name='ground_plane'>
        <pose>0 0 0 0 -0 0</pose>
        <scale>1 1 1</scale>
        <link name='link'>
          <pose>0 0 0 0 -0 0</pose>
          <velocity>0 0 0 0 -0 0</velocity>
          <acceleration>0 0 0 0 -0 0</acceleration>
          <wrench>0 0 0 0 -0 0</wrench>
        </link>
      </model>
      <model name='husky'>
        <pose>3.80807 -2.81864 0.142755 -7e-06 4e-06 -0.008644</pose>
        <scale>1 1 1</scale>
        <link name='back_left_wheel'>
          <pose>3.55455 -2.53097 0.177754 -3.6e-05 -0.176224 -0.00864</pose>
          <velocity>-0.000999 0.000997 0.000189 -0.005475 -0.005253 0.001125</velocity>
          <acceleration>-0.383546 0.545149 -1.12862 0.049907 -0.508326 1.37059</acceleration>
          <wrench>-1.01091 1.43685 -2.97471 0 -0 0</wrench>
        </link>
        <link name='back_right_wheel'>
          <pose>3.54961 -3.10189 0.177757 -5e-06 -0.030339 -0.008644</pose>
          <velocity>-0.000279 0.001093 0.002197 -0.003885 0.003964 0.001266</velocity>
          <acceleration>-0.85668 0.644284 -5.03253 -1.26768 0.010954 -0.927135</acceleration>
          <wrench>-2.25795 1.69814 -13.2642 0 -0 0</wrench>
        </link>
        <link name='base_link'>
          <pose>3.80807 -2.81864 0.142755 -7e-06 4e-06 -0.008644</pose>
          <velocity>-0.000785 0.001301 0.000103 -0.003427 0.004191 0.001272</velocity>
          <acceleration>0.221271 -0.450267 -3.82068 -2.77327 -0.973606 2.39357</acceleration>
          <wrench>7.49112 -15.2438 -129.349 0 -0 0</wrench>
        </link>
        <link name='front_left_wheel'>
          <pose>4.06653 -2.53539 0.177752 -2.8e-05 0.275643 -0.008649</pose>
          <velocity>-0.000978 0.002015 -0.001978 0.001609 -0.00289 0.000623</velocity>
          <acceleration>-0.384806 0.779845 -3.22531 2.14556 -0.072879 -2.0475</acceleration>
          <wrench>-1.01423 2.05544 -8.50096 0 -0 0</wrench>
        </link>
        <link name='front_right_wheel'>
          <pose>4.06159 -3.10632 0.177756 -2e-06 0.005593 -0.008644</pose>
          <velocity>-0.000272 0.001461 -3.7e-05 -0.008157 -0.001134 0.001241</velocity>
          <acceleration>-0.844315 0.190972 -7.33182 -0.925522 1.26754 -0.817369</acceleration>
          <wrench>-2.22536 0.503346 -19.3245 0 -0 0</wrench>
        </link>
      </model>
      <model name='polaris_ranger_ev'>
        <pose>-1.21453 2.58906 0.00027 -9.1e-05 6.2e-05 -0.002894</pose>
        <scale>1 1 1</scale>
        <link name='FNR_switch'>
          <pose>-0.654527 2.56754 1.08024 -9.2e-05 0.086038 -0.002902</pose>
          <velocity>-0.001369 -0.003461 -0.006001 0.004432 -0.001792 -0.000282</velocity>
          <acceleration>-6.2e-05 0 -2e-05 0 2e-05 -7e-06</acceleration>
          <wrench>-6e-06 0 -2e-06 0 -0 0</wrench>
        </link>
        <link name='brake_pedal'>
          <pose>-0.505123 2.85706 0.539042 -9.2e-05 6.4e-05 -0.002894</pose>
          <velocity>-0.000321 -0.001106 -0.004433 0.004477 -0.001907 -0.000284</velocity>
          <acceleration>-6.9e-05 1e-06 -2.2e-05 1e-06 1.4e-05 1e-06</acceleration>
          <wrench>-7e-06 0 -2e-06 0 -0 0</wrench>
        </link>
        <link name='chassis'>
          <pose>-1.21453 2.58906 0.00027 -9.1e-05 6.2e-05 -0.002894</pose>
          <velocity>0.000582 0.001459 -0.006928 0.00439 -0.001791 -0.000279</velocity>
          <acceleration>-7.1e-05 1e-06 -1.4e-05 1e-06 1.3e-05 6e-06</acceleration>
          <wrench>-0.051237 0.000456 -0.009743 0 -0 0</wrench>
        </link>
        <link name='front_left_wheel'>
          <pose>-0.180725 3.18608 0.320233 1.49907 -0.812835 -3.11233</pose>
          <velocity>0.000185 -0.000865 -0.011037 0.004403 0.000515 -4.7e-05</velocity>
          <acceleration>-7.6e-05 0 -4.3e-05 -1e-06 -0.000115 5.7e-05</acceleration>
          <wrench>-0.000917 1e-06 -0.000522 0 -0 0</wrench>
        </link>
        <link name='front_left_wheel_steering_block'>
          <pose>-0.183073 3.08611 0.320265 1.57071 6e-05 -0.023474</pose>
          <velocity>0.000174 -0.000875 -0.013895 0.004083 -0.00178 -0.000177</velocity>
          <acceleration>-7.3e-05 -0 -4.9e-05 0 1.4e-05 3.8e-05</acceleration>
          <wrench>-7.3e-05 -0 -4.9e-05 0 -0 0</wrench>
        </link>
        <link name='front_right_wheel'>
          <pose>-0.186901 1.98612 0.320279 -1.4995 -0.803733 3.08028</pose>
          <velocity>-0.000174 -0.001105 -0.006162 0.002509 -0.000389 -0.00045</velocity>
          <acceleration>-7.6e-05 2e-06 -4.3e-05 0 -0.000114 -5.4e-05</acceleration>
          <wrench>-0.000911 2.2e-05 -0.000511 0 -0 0</wrench>
        </link>
        <link name='front_right_wheel_steering_block'>
          <pose>-0.185966 2.08612 0.320275 1.57071 6.2e-05 -0.009345</pose>
          <velocity>-0.000136 -0.001108 -0.005287 0.004152 -0.001809 -0.000379</velocity>
          <acceleration>-7.2e-05 2e-06 -4.7e-05 1e-06 1.4e-05 -3.6e-05</acceleration>
          <wrench>-7.2e-05 2e-06 -4.7e-05 0 -0 0</wrench>
        </link>
        <link name='gas_pedal'>
          <pose>-0.527647 2.68712 0.52365 -9.2e-05 6.3e-05 -0.002894</pose>
          <velocity>-0.00034 -0.00103 -0.005236 0.004445 -0.001883 -0.000282</velocity>
          <acceleration>-7e-05 1e-06 -2.2e-05 1e-06 1.4e-05 0</acceleration>
          <wrench>-7e-06 0 -2e-06 0 -0 0</wrench>
        </link>
        <link name='hand_brake'>
          <pose>-0.684269 2.65762 1.05023 -9.3e-05 -0.163787 -0.002879</pose>
          <velocity>-0.001289 -0.00332 -0.005655 0.004432 -0.001793 -0.000284</velocity>
          <acceleration>-6.2e-05 0 -1.9e-05 2e-06 1.8e-05 1e-06</acceleration>
          <wrench>-3.1e-05 0 -1e-05 0 -0 0</wrench>
        </link>
        <link name='rear_left_wheel'>
          <pose>-2.06277 3.19155 0.320267 1.49904 -0.812672 -3.09173</pose>
          <velocity>0.000185 -8.6e-05 -0.00561 0.001105 0.000524 -0.000138</velocity>
          <acceleration>-7.3e-05 0 0 -6.4e-05 -0.028097 -0.01386</acceleration>
          <wrench>-0.00087 2e-06 3e-06 0 -0 0</wrench>
        </link>
        <link name='rear_right_wheel'>
          <pose>-2.06631 1.99155 0.320237 -1.49954 -0.803484 3.08677</pose>
          <velocity>-0.00016 -0.000292 -0.011151 -0.000804 -0.000378 -0.00035</velocity>
          <acceleration>-7.2e-05 0 -1e-06 0.0001 0.028584 0.005444</acceleration>
          <wrench>-0.000864 2e-06 -1e-05 0 -0 0</wrench>
        </link>
        <link name='steering_wheel'>
          <pose>-0.873596 2.88797 1.29021 0.130188 -0.862714 -0.173657</pose>
          <velocity>-0.001658 -0.004331 -0.004976 0.004407 -0.001806 -0.00026</velocity>
          <acceleration>-5.9e-05 -0 -1.7e-05 -2e-06 5e-06 -0</acceleration>
          <wrench>-5.9e-05 -0 -1.7e-05 0 -0 0</wrench>
        </link>
      </model>
      <model name='postbox'>
        <pose>2.03099 2.66028 0 0 -0 0</pose>
        <scale>1 1 1</scale>
        <link name='link'>
          <pose>2.03099 2.66028 0 0 -0 0</pose>
          <velocity>0 0 0 0 -0 0</velocity>
          <acceleration>0 0 0 0 -0 0</acceleration>
          <wrench>0 0 0 0 -0 0</wrench>
        </link>
      </model>
      <light name='sun'>
        <pose>0 0 10 0 -0 0</pose>
      </light>
    </state>
    <gui fullscreen='0'>
      <camera name='user_camera'>
        <pose>25.0906 -18.4772 37.3877 -0 0.899643 2.38419</pose>
        <view_controller>orbit</view_controller>
        <projection_type>perspective</projection_type>
      </camera>
    </gui>
  </world>
</sdf>
